<?xml version="1.0"?>
<robot name="adeept_awr">

<!-- Chassis -->
  <link name="chassis">
    <origin xyz = "0.0 0.0 0.055"/>
    <visual>
      <geometry>
        <box size = "0.13 0.12 0.08"/>
      </geometry>
    </visual>
    <collision>
      <geometry>
        <box size = "0.13 0.12 0.08"/>
      </geometry>
    </collision>
    <inertial>
      <origin xyz="0.0 0.0125 0.0"/>
      <mass value="0.100"/>
      <inertia ixx="0.00009565" ixy="0.0" ixz="0" iyy="0.0003999" iyz="0.0" izz="0.0004892"/>
    </inertial>
  </link>

  <!-- Camera -->
  <joint name="camera_joint" type="fixed">
    <origin xyz="0.07 0.0 0.03" rpy="0 0 0"/>
    <parent link="chassis"/>
    <child link="camera_link"/>
  </joint>
  <link name="camera_link">
    <collision>
      <origin xyz="0.07 0.0 0.03" rpy="0 0 0"/>
      <geometry>
    	  <box size="1e-6 1e-6 1e-6"/>
      </geometry>
    </collision>

    <visual>
      <origin xyz="0.07 0.0 0.03" rpy="0 0 0"/>
      <geometry>
    	  <box size="1e-6 1e-6 1e-6"/>
      </geometry>
    </visual>

    <inertial>
      <mass value="1e-6" />
      <origin xyz="0 0 0" rpy="0 0 0"/>
      <inertia ixx="1e-6" ixy="0" ixz="0" iyy="1e-6" iyz="0" izz="1e-6" />
    </inertial>
  </link>

  <!-- Battery -->
  <link name="battery">
    <origin xyz = "0.0 0.0 0.0"/>
    <visual>
      <geometry>
        <box size = "0.145 0.065 0.015"/>
      </geometry>
    </visual>
    <collision>
      <geometry>
        <box size = "0.145 0.065 0.015"/>
      </geometry>
    </collision>
    <inertial>
      <origin xyz = "0.0 0.0 0.0"/>
      <mass value="0.005"/>
      <inertia ixx="0.00009435" ixy="0.0" ixz="0" iyy="0.00001117" iyz="0.0" izz="0.0000148"/>
    </inertial>
  </link>

  <!-- Wheels -->
  <link name="front_left_wheel">
    <visual>
      <origin xyz="0.0 0.0125 0.0" rpy="1.5708 0 0"/>
      <geometry>
        <cylinder radius="0.0325" length="0.025"/>
      </geometry>
    </visual>
    <collision>
      <origin xyz="0.0 0.0125 0.0" rpy="1.5708 0 0"/>
      <geometry>
        <cylinder radius="0.0325" length="0.025"/>
      </geometry>
    </collision>
    <inertial>
      <origin xyz="0.0 0.0125 0.0"/>
      <mass value="0.03"/>
      <inertia ixx="0.00001044" ixy="0.0" ixz="0" iyy="0.00001767" iyz="0.0" izz="0.00001044"/>
    </inertial>
  </link>
  <link name="front_right_wheel">
    <visual>
      <origin xyz="0.0 -0.0125 0.0" rpy="1.5708 0 0"/>
      <geometry>
        <cylinder radius="0.0325" length="0.025"/>
      </geometry>
    </visual>
    <collision>
      <origin xyz="0.0 -0.0125 0.0" rpy="1.5708 0 0"/>
      <geometry>
        <cylinder radius="0.0325" length="0.025"/>
      </geometry>
    </collision>
    <inertial>
      <origin xyz="0.0 -0.0125 0.0"/>
      <mass value="0.03"/>
      <inertia ixx="0.00001044" ixy="0.0" ixz="0" iyy="0.00001767" iyz="0.0" izz="0.00001044"/>
    </inertial>
  </link>
  <link name="rear_left_wheel">
    <visual>
      <origin xyz="0.0 0.0125 0.0" rpy="1.5708 0 0"/>
      <geometry>
        <cylinder radius="0.0325" length="0.025"/>
      </geometry>
    </visual>
    <collision>
      <origin xyz="0.0 0.0125 0.0" rpy="1.5708 0 0"/>
      <geometry>
        <cylinder radius="0.0325" length="0.025"/>
      </geometry>
    </collision>
    <inertial>
      <origin xyz="0.0 0.0125 0.0"/>
      <mass value="0.03"/>
      <inertia ixx="0.00001044" ixy="0.0" ixz="0" iyy="0.00001767" iyz="0.0" izz="0.00001044"/>
    </inertial>
  </link>
  <link name="rear_right_wheel">
    <visual>
      <origin xyz="0.0 -0.0125 0.0" rpy="1.5708 0 0"/>
      <geometry>
        <cylinder radius="0.0325" length="0.025"/>
      </geometry>
    </visual>
    <collision>
      <origin xyz="0.0 -0.0125 0.0" rpy="1.5708 0 0"/>
      <geometry>
        <cylinder radius="0.0325" length="0.025"/>
      </geometry>
    </collision>
    <inertial>
      <origin xyz="0.0 -0.0125 0.0"/>
      <mass value="0.03"/>
      <inertia ixx="0.00001044" ixy="0.0" ixz="0" iyy="0.00001767" iyz="0.0" izz="0.00001044"/>
    </inertial>
  </link>

  <!-- Joints -->
  <joint name = "battery_mount" type="fixed">
    <parent link = "chassis"/>
    <child link = "battery"/>
    <origin xyz = "0.015 0.0 0.0475"/>
  </joint>
  <joint name = "rear_right_axle" type="continuous">
    <parent link = "chassis"/>
    <child link = "rear_right_wheel"/>
    <origin xyz = "-0.05 -0.06 -0.02"/>
    <axis xyz = "0 1 0" />
    <limit effort = "0.0784532" velocity="1.55"/>
    <dynamics friction="0.04"/>
  </joint>
  <joint name = "rear_left_axle" type="continuous">
    <parent link = "chassis"/>
    <child link = "rear_left_wheel"/>
    <origin xyz = "-0.05 0.06 -0.02"/>
    <axis xyz = "0 1 0" />
    <limit effort = "0.0784532" velocity="1.55"/>
    <dynamics friction="0.04"/>
  </joint>
  <joint name = "front_left_axle" type="continuous">
    <parent link = "chassis"/>
    <child link = "front_left_wheel"/>
    <origin xyz = "0.03 0.06 -0.02"/>
    <axis xyz = "0 1 0" />
    <limit effort = "0.0784532" velocity="1.55"/>
    <dynamics friction="0.04"/>
  </joint>
  <joint name = "front_right_axle" type="continuous">
    <parent link = "chassis"/>
    <child link = "front_right_wheel"/>
    <origin xyz = "0.03 -0.06 -0.02"/>
    <axis xyz = "0 1 0" />
    <limit effort = "0.0784532" velocity="1.55"/>
    <dynamics friction="0.04"/>
  </joint>

  <!-- Camera plugin -->
  <gazebo reference="camera_link">
    <material>Gazebo/Blue</material>

    <sensor name="camera" type="camera">
      <always_on>true</always_on>
      <visualize>true</visualize>
      <update_rate>15</update_rate>
      <topic>camera/image_raw</topic>
      <gz_frame_id>camera_rgb_frame</gz_frame_id>
      <camera name="PiCam">
        <camera_info_topic>camera/camera_info</camera_info_topic>
        <horizontal_fov>2.35</horizontal_fov>
          <image>
            <width>1280</width>
            <height>720</height>
            <format>R8G8B8</format>
          </image>
          <clip>
            <near>0.02</near>
            <far>300</far>
          </clip>
          <noise>
            <type>gaussian</type>
            <!-- Noise is sampled independently per pixel on each frame.
                That pixel's noise value is added to each of its color
                channels, which at that point lie in the range [0,1]. -->
            <mean>0.0</mean>
            <stddev>0.007</stddev>
          </noise>
      </camera>
    </sensor>
  </gazebo>

  <!-- Differential Drive -->
  <gazebo>
    <plugin filename="gz-sim-diff-drive-system" name="gz::sim::systems::DiffDrive">
      <!-- wheels -->
      <left_joint>rear_left_axle</left_joint>
      <right_joint>rear_right_axle</right_joint>

      <!-- kinematics -->
      <wheel_separation>0.13</wheel_separation>
      <wheel_radius>0.033</wheel_radius> <!-- computed from <wheel_diameter> in the original plugin-->

      <!-- limits -->
      <max_linear_acceleration>0.033</max_linear_acceleration> <!-- computed from <max_linear_acceleration> in the original plugin-->

      <topic>cmd_vel</topic> <!-- from <commant_topic> -->

      <odom_topic>odom</odom_topic> <!-- from <odometry_topic> -->
      <frame_id>odom</frame_id> <!-- from <odometry_frame> -->
      <child_frame_id>base_footprint</child_frame_id> <!-- from <robot_base_frame> -->
      <odom_publisher_frequency>30</odom_publisher_frequency> <!-- from <update_rate>-->

      <tf_topic>/tf</tf_topic> <!-- Short topic name for tf output -->
    </plugin>
  </gazebo>

  <gazebo>
    <plugin filename="gz-sim-joint-state-publisher-system"
      name="gz::sim::systems::JointStatePublisher">
      <topic>joint_states</topic> <!--from <ros><remapping> -->
      <joint_name>rear_left_axle</joint_name>
      <joint_name>rear_right_axle</joint_name>
    </plugin>
  </gazebo>
</robot>